Workbook

Sheet CAPA DO LAUDO
B3: LAUDO DE AVALIAÇÃO Nº 435420
B7: Proponente:
B8: Processo:
B9: Agência Solicitante:
B10: Objetivo:
B11: Objeto:
B12: Local e Data:
B17: QUADRO RESUMO DA AVALIAÇÃO
B19: Proponente:
B20: Agência Solicitante:
B21: Identificação:
B22: Município:
B23: IMÓVEL
B24: Nº Matrícula | E24: Identificação | H24: Área Superficial há | K24: Área Construída m²
B27: CROQUI
B34: VALORES
B35: MATRÍCULA | F35: MERCADO R$ | J35: LIQUIDAÇÃO FORÇADA R$
B38: TOTAL
B39: OBSERVAÇÕES

Sheet FATORES
D9: HIDROGRAFIA
D10: 1,30 a 1,50 - (MUITO BOM) | E10: 1.2
D11: 1,15 a 1,29 - (BOM) | E11: 1.1
D12: 1,01 a 1,14 - (NORMAL) | E12: 1
D13: 1,00 - (REGULAR) | E13: 0.9
D14: 0,80 a 0,99 - (RUIM) | E14: 0.8
D15: 0,50 a 0,79 - (MUITO RUIM) | E15: 0.7
D17: FONTE: DESLANDES, CRISTIANO AUGUSTO - AVALIAÇÃO DE IMÓVEIS RURAIS (2002).
D18: FONTE: GLOSSÁRIO INTERNACIONAL DE HIDROLOGIA (UNESCO).
D21: BENFEITORIAS | E21: Fatores
D22: MUITO ACIMA DA MÉDIA | E22: 1.2
D23: ACIMA DA MÉDIA | E23: 1.1
D24: MÉDIA | E24: 1
D25: ABAIXO DA MÉDIA | E25: 0.9
D26: MUITO ABAIXO DA MÉDIA | E26: 0.8
D27: SEM BENFEITORIA | E27: 0.7
D32: Situação | E32: CARACTERÍSTICA
E33: Tipo de Estrada | F33: Trafegabilidade | G33: Fatores
D34: Ótima | E34: Pavimentada com asfalto/concreto | F34: Permanente | G34: 1.2
D35: Muito Boa | E35: Pavimentada com cascalhamento/intertravado | F35: Permanente | G35: 1.1
D36: Boa | E36: Não Pavimentada | F36: Permanente | G36: 1
D37: Desfavorável | E37: Não Pavimentada e Servidões de Passagem | F37: Problemas sérios nas Estações chuvosas | G37: 0.9
D38: Má | E38: Servidões com a presença de fechos | G38: 0.8
D39: Péssima | E39: Fechos e interceptados por córregos sem pontes | F39: Problemas sérios mesmo nas secas | G39: 0.7

Sheet AREA UTIL 
O3: APP | P3: ARL
C4: MATRÍCULA 5.723 | O4: 13.6783 | P4: 141.8504 | Q4: =P4+O4
C5: AREA TOTAL | E5: AREA DE RESERVA LEGAL | G5: AREA DE APP | I5: ÁREA CONSTRUÍDA | N5: AU
C6: =AMOSTRAS!E6 | E6: - | G6: - | I6: - | L6: 231.63 | N6: =L6+7.12 | R6: =P4+O4+N6
C7: CERTIFICADO DE CADASTRO DE IMÓVEL RURAL - CCIR | R7: =C6-R6 | S7: AR
C8: AREA TOTAL | E8: CLASSIFICAÇÃO FUNDIÁRIA | G8: MÓDULO RURAL | I8: Nº DE MÓDULOS RURAIS
C9: 387.2 | E9: Média Propriedade Proditova | G9: 80 | I9: 4.84
C10: CADASTRO AMBIENTAL RURAL - CAR
C11: AREA TOTAL | E11: AREA DE RESERVA LEGAL | G11: AREA DE APP | I11: ÁREA CONSOLIDADA
C12: 769.477 | E12: 271.2444 | G12: 23.6993 | I12: -
C13: SITUAÇÃO | E13: Ativo | G13: CONDIÇÃO | I13: Aguardando Análise
C16: =C4
C17: USO DA TERRA | F17: ÁREA (ha) | H17: % ÁREA
C18: Área de Vegetação Remanescente | F18: =AMOSTRAS!E11 | H18: =AMOSTRAS!F11
C19: Área De Reserva Legal e APP | F19: =AMOSTRAS!E12 | H19: =F19/C6
C20: SOMATÓRIA | F20: =SUM(F18:G19) | H20: =SUM(H18:I19)

Sheet AMOSTRAS
B3: AVALIANDA | L3: MÉDIA DAS AMOSTRAS
C4: Proprietário(s): | E4: Marcelo Daniel Fell | G4: Contato: | H4: (77) 99993-8091 | L4: R$/ ha = | M4: =SUM(H19+H32+H45+H58+H71+H84)/6
B5: Localização do Imóvel: | E5: Almas - TO | G5: Situação: | H5: Muito Boa | L5: Alq = | M5: =M4*4.84
B6: Área do Imóvel (ha): | E6: 569.0049 | G6: Benfeitoria: | H6: Sem Benfeitorias
C7: Hidrografia: | E7: Normal | G7: Data: | H7: =TODAY()
C8: Matrícula: | E8: 5404 | G8: Outros:
B9: Nota Agronômica da Amostra
B10: Classe de Solo | E10: Área (ha) | F10: % do Imóvel | G10: Nota Agronômica
C11: V | E11: =E6-E12 | F11: =E11/E6 | G11: 0.9
B12: VIII | E12: 218.9 | F12: =E12/E6 | G12: 0.6
B13: SOMATÓRIA | E13: =SUM(E11:E12) | F13: =SUM(F11:F12) | G13: =F12*G12+F11*G11
B15: Dado Amostral 01
B16: Proprietário / Informante: | E16: OLX | G16: Contato: | H16: (62) 4102-3282
B17: Localização do Imóvel: | E17: Almas - TO | G17: Situação: | H17: Boa
B18: Área do Imóvel (ha): | E18: =287 *4.84 | G18: Benfeitoria: | H18: Muito Abaixo da Média
C19: Valor venal: | E19: 12915000 | G19: Valor R$/ha: | H19: =E19/E18 | J19: =H19*4.84
C20: Negociação: | E20: Oferta | G20: Data: | H20: 45566
C21: Hidrografia: | E21: Normal | G21: Outros:
B22: Nota Agronômica da Amostra
B23: Classe de Solo | E23: Área (ha) | F23: % do Imóvel | G23: Nota Agronômica
B24: IV | E24: =E18*0.5 | F24: =E24/E18 | G24: 1
B25: VIII | E25: =E18-E24 | F25: =E25/E18 | G25: 0.6
B26: SOMATÓRIA | E26: =SUM(E24:E25) | F26: 1 | G26: 0.73333333
B28: Dado Amostral 02
B29: Proprietário / Informante: | E29: POINTER NEGOCIOS DE FAZENDAS | G29: Contato: | H29: (62) 4102-3282 | K29: https://www.wimoveis.com.br/propriedades/fazenda-com-2-dormitorios-a-venda-40414000-m-sup2-2979429591.html
B30: Localização do Imóvel: | E30: Almas - TO | G30: Situação: | H30: Boa
B31: Área do Imóvel (ha): | E31: 4035 | G31: Benfeitoria: | H31: Muito Abaixo da Média
C32: Valor venal: | E32: 37580000 | G32: Valor R$/ha: | H32: =E32/E31 | J32: =H32*4.84
C33: Negociação: | E33: Oferta | G33: Data: | H33: =H20
C34: Hidrografia: | E34: Ruim | G34: Outros:
B35: Nota Agronômica da Amostra
B36: Classe de Solo | E36: Área (ha) | F36: % do Imóvel | G36: Nota Agronômica
B37: IV | E37: 275 | F37: =E37/E31 | G37: 1
B38: VIII | E38: 3760 | F38: =E38/E31 | G38: 0.6
B39: SOMATÓRIA | E39: 4035 | F39: 1 | G39: 0.62726146
B41: Dado Amostral 03 | K41: https://www.wimoveis.com.br/propriedades/fazenda-a-venda-na-regiao-de-almas-to-2985494046.html
B42: Proprietário / Informante: | E42: PARNAÍBA IMOVEIS | G42: Contato: | H42: (11) 41545889
B43: Localização do Imóvel: | E43: Almas - TO | G43: Situação: | H43: Boa
B44: Área do Imóvel (ha): | E44: 1326.16 | G44: Benfeitoria: | H44: Muito Abaixo da Média
C45: Valor venal: | E45: 16400000 | G45: Valor R$/ha: | H45: =E45/E44 | J45: =H45*4.84
...

Sheet QUADRO
B3: ELEMENTO | C3: ÁREA (ha) | D3: VT (R$) | E3: VT(R$/ha) | F3: CLASSE | G3: SITUAÇÃO | H3: BENFEITORIAS | I3: HIDROGRAFIA | J3: FONTE | K3: INFORMANTE | L3: CONTATO
B4: 1 | C4: =AMOSTRAS!E18 | D4: =AMOSTRAS!E19 | E4: =D4/C4 | F4: =AMOSTRAS!G26 | G4: 1 | H4: 0.8 | I4: 1 | J4: 0.9 | K4: =AMOSTRAS!E16 | L4: =AMOSTRAS!H16
B5: 2 | C5: =AMOSTRAS!E31 | D5: =AMOSTRAS!E32 | E5: =D5/C5 | F5: =AMOSTRAS!G39 | G5: 1 | H5: 0.8 | I5: 1 | J5: 0.9 | K5: =AMOSTRAS!E29 | L5: =AMOSTRAS!H29
B6: 3 | C6: =AMOSTRAS!E44 | D6: =AMOSTRAS!E45 | E6: =D6/C6 | F6: =AMOSTRAS!G52 | G6: 1 | H6: 0.8 | I6: 1 | J6: 0.9 | K6: =AMOSTRAS!E42 | L6: =AMOSTRAS!H42
B7: 4 | C7: =AMOSTRAS!E57 | D7: =AMOSTRAS!E58 | E7: =D7/C7 | F7: =AMOSTRAS!G65 | G7: 1 | H7: 0.8 | I7: 1 | J7: 0.9 | K7: =AMOSTRAS!E55 | L7: =AMOSTRAS!H55
B8: 5 | C8: =AMOSTRAS!E70 | D8: =AMOSTRAS!E71 | E8: =D8/C8 | F8: =AMOSTRAS!G78 | G8: 1 | H8: 0.8 | I8: 1 | J8: 0.9 | K8: =AMOSTRAS!E68 | L8: =AMOSTRAS!H68
B9: 6 | C9: =AMOSTRAS!E83 | D9: =AMOSTRAS!E84 | E9: =D9/C9 | F9: =AMOSTRAS!G91 | G9: 1 | H9: 0.8 | I9: 1 | J9: 0.9 | K9: =AMOSTRAS!E81 | L9: =AMOSTRAS!H81

Sheet PLANILHA HOMOG
A3: Elemento | B3: Municipio | C3: Imóvel | D3: Valor do Imóvel R$ | E3: Área Total Do Imóvel (ha) | F3: Valor por hectare (R$/ha) | G3: CCU do Elemento | H3: CCU Indexado 1 | I3: Situação Elemento | J3: Situação Indexado² | K3: Benfeitorias | L3: Benfeitorias Indexado³ | M3: Hidrografia Elemento | N3: Hidrografia Indexado 4 | O3: Fator Oferta Elemento | P3: Fator Homogeneização Total (FHT) 6 | Q3: VT/ha homogeneizado 7 | R3: Amostra Saneada
A4: 1 | B4: =AMOSTRAS!E17 | C4: Imóvel 1 | D4: =AMOSTRAS!E19 | E4: =AMOSTRAS!E18 | F4: =D4/E4 | G4: =AMOSTRAS!G26 | H4: =IF(G10=" ","",$G$10-G4+1) | I4: =QUADRO!G4 | J4: =IF(I10=" ","",$I$10-I4+1) | K4: =QUADRO!H4 | L4: =IF(K10=" ","",$K$10-K4+1) | M4: =QUADRO!I4 | N4: =IF(M10=" ","",$M$10-M4+1) | O4: =QUADRO!J4 | P4: =TRUNC(IF(O4=" ","",H4*J4*L4*N4*O4),4) | Q4: =TRUNC(IF(F4="","",F4*P4),2) | R4: =IF(AND(Q4<=$Q$12+$Q$13,Q4>=$Q$12-$Q$13),Q4,"*")
A5: 2 | B5: =AMOSTRAS!E30 | C5: Imóvel 2 | D5: =AMOSTRAS!E32 | E5: =AMOSTRAS!E31 | F5: =D5/E5 | G5: =AMOSTRAS!G39 | H5: =IF(G10=" ","",$G$10-G5+1) | I5: =QUADRO!G5 | J5: =IF(I10=" ","",$I$10-I5+1) | K5: =QUADRO!H5 | L5: =IF(K10=" ","",$K$10-K5+1) | M5: =QUADRO!I5 | N5: =IF(M10=" ","",$M$10-M5+1) | O5: =QUADRO!J5 | P5: =TRUNC(IF(O5=" ","",H5*J5*L5*N5*O5),4) | Q5: =TRUNC(IF(F5="","",F5*P5),2) | R5: =IF(AND(Q5<=$Q$12+$Q$13,Q5>=$Q$12-$Q$13),Q5,"*")
A6: 3 | B6: =AMOSTRAS!E43 | C6: Imóvel 3 | D6: =AMOSTRAS!E45 | E6: =AMOSTRAS!E44 | F6: =D6/E6 | G6: =AMOSTRAS!G52 | H6: =IF(G10=" ","",$G$10-G6+1) | I6: =QUADRO!G6 | J6: =IF(I10=" ","",$I$10-I6+1) | K6: =QUADRO!H6 | L6: =IF(K10=" ","",$K$10-K6+1) | M6: =QUADRO!I6 | N6: =IF(M10=" ","",$M$10-M6+1) | O6: =QUADRO!J6 | P6: =TRUNC(IF(O6=" ","",H6*J6*L6*N6*O6),4) | Q6: =TRUNC(IF(F6="","",F6*P6),2) | R6: =IF(AND(Q6<=$Q$12+$Q$13,Q6>=$Q$12-$Q$13),Q6,"*")
A7: 4 | B7: =AMOSTRAS!E56 | C7: Imóvel 4 | D7: =AMOSTRAS!E58 | E7: =AMOSTRAS!E57 | F7: =D7/E7 | G7: =AMOSTRAS!G65 | H7: =IF(G11=" ","",$G$10-G7+1) | I7: =QUADRO!G7 | J7: =IF(I11=" ","",$I$10-I7+1) | K7: =QUADRO!H7 | L7: =IF(K11=" ","",$K$10-K7+1) | M7: =QUADRO!I7 | N7: =IF(M11=" ","",$M$10-M7+1) | O7: =QUADRO!J7 | P7: =TRUNC(IF(O7=" ","",H7*J7*L7*N7*O7),4) | Q7: =TRUNC(IF(F7="","",F7*P7),2) | R7: =IF(AND(Q7<=$Q$12+$Q$13,Q7>=$Q$12-$Q$13),Q7,"*")
A8: 5 | B8: =AMOSTRAS!E69 | C8: Imóvel 5 | D8: =AMOSTRAS!E71 | E8: =AMOSTRAS!E70 | F8: =D8/E8 | G8: =AMOSTRAS!G78 | H8: =IF(G12=" ","",$G$10-G8+1) | I8: =QUADRO!G8 | J8: =IF(I12=" ","",$I$10-I8+1) | K8: =QUADRO!H8 | L8: =IF(K12=" ","",$K$10-K8+1) | M8: =QUADRO!I8 | N8: =IF(M12=" ","",$M$10-M8+1) | O8: =QUADRO!J8 | P8: =TRUNC(IF(O8=" ","",H8*J8*L8*N8*O8),4) | Q8: =TRUNC(IF(F8="","",F8*P8),2) | R8: =IF(AND(Q8<=$Q$12+$Q$13,Q8>=$Q$12-$Q$13),Q8,"*")
A9: 6 | B9: =AMOSTRAS!E82 | C9: Imóvel 6 | D9: =AMOSTRAS!E84 | E9: =AMOSTRAS!E83 | F9: =D9/E9 | G9: =AMOSTRAS!G91 | H9: =IF(G13=" ","",$G$10-G9+1) | I9: =QUADRO!G9 | J9: =IF(I13=" ","",$I$10-I9+1) | K9: =QUADRO!H9 | L9: =IF(K13=" ","",$K$10-K9+1) | M9: =QUADRO!I9 | N9: =IF(M13=" ","",$M$10-M9+1) | O9: =QUADRO!J9 | P9: =TRUNC(IF(O9=" ","",H9*J9*L9*N9*O9),4) | Q9: =TRUNC(IF(F9="","",F9*P9),2) | R9: =IF(AND(Q9<=$Q$12+$Q$13,Q9>=$Q$12-$Q$13),Q9,"*")
A10: Avaliando | B10: =AMOSTRAS!E5 | C10: AVALIANDA | G10: =AMOSTRAS!G13 | I10: 0.9 | K10: 0.7 | M10: 1.1
A12: CCU Indexado¹ | C12: obtido da seguinte forma = (CCU imóvel Avaliando - CCU elmento da amostra) + 1 | P12: Média | Q12: =TRUNC(AVERAGE(Q4:Q9),2)
A13: Situação Indexado ² | C13: obtido da seguinte forma = (Situação imóvel Avaliando - Situação elmento da amostra) + 1 | P13: Desvio Padrão | Q13: =TRUNC(IF(Q12="","",_xlfn.STDEV.S(Q4:Q9)),2)
A14: =L3 | C14: obtido da seguinte forma = (Distância imóvel Avaliando - Distância elmento da amostra) + 1 | P14: Limite Superior | Q14: =TRUNC(IF(Q12="","",Q12+Q13),2)
A15: Hidrografia Indexado 4 | C15: obtido da seguinte forma = (Hidrografia imóvel Avaliando - Hidrografia elmento da amostra) + 1 | P15: Limite Inferior | Q15: =TRUNC(IF(Q12="","",Q12-Q13),2)
A16: Fator Homogeneização Total (FHT) 6 | C16: Obtido pela multiplicação do CCU Indexado, da Situação Indexado, Distância Indexado, Hidrografia Indexado e Fator Oferta
A17: VT/ha homogeneizado 7 | C17: Resultado da multiplicação do VT / ha do elementdo da amostra pelo seu FHT | M17: n = | N17: 4 | P17: Média após Saneamento | Q17: =TRUNC(AVERAGE(R4:R9),2)
A18: Limite Superior | C18: Limite superior de valor de VT/ha homogeneizado | M18: t = | N18: 0.271
A19: Limite Inferior | C19: Limite Inferior de valor de VT/ha homogeneizado | P19: Desvio Padrão Saneado | Q19: =TRUNC(_xlfn.STDEV.S(R4:R9),2)
A20: Amostra Saneada | C20: Elemento que apresente seu VT/ ha homogeneizado maior que o limite superior ou menor que o limite inferior | P20: Fator para I.C. | Q20: =TRUNC(N18*(Q19/(SQRT(N17))),2)
A21: Média após Saneamento | C21: Média de Valor calculado após eliminação dos elementos saneados | P21: I.C. Superior | Q21: =TRUNC(IF(Q17="","",Q17+Q20),2)
A22: Fator para I.C. | C22: = t*(Desvio padrão saneado/ √ do numero de elementos utilizado), onde "t" é percentil da distribuição de Student, com grau de liberdade ( V = n-1) e 80% de confiança | P22: I.C. Inferior | Q22: =TRUNC(IF(Q17="","",Q17-Q20),2)
A23: I.C. Superior | C23: Média Saneada + Fator para I.C. | P23: Amplitude | Q23: =TRUNC(IF(Q21="","",Q21-Q22),2)
A24: I.C. Inferior | C24: Média Saneada - Fator para I.C. | P24: Coeficiente de Variação % | Q24: =IF(Q17="","",(Q23/Q17)*100)
A25: Amplitude | C25: I.C. Superior - I.C. Inferior
A26: Coeficiente de Variação | C26: Amplitude / Média Saneada
P29: =Q17*4.84

Sheet SANEAMENTO
C4: ='AREA UTIL '!C4:J4
C5: SANEAMENTO DAS AMOSTRAS
C6: Desvio Padrão Saneado | F6: ='PLANILHA HOMOG'!Q19
C7: Limite Superior (R$/ha) | F7: ='PLANILHA HOMOG'!Q14
C8: Limite Inferior (R$/ha) | F8: ='PLANILHA HOMOG'!Q15
C9: Elementos Saneados | F9: 6 | J9: PREENCHER MANUAL
C10: Elementos Expurgados | F10: 1 | J10: PREENCHER MANUAL
C11: Coeficiente de Variação % | F11: ='PLANILHA HOMOG'!Q24
C12: T. Student | F12: ='PLANILHA HOMOG'!N18
C13: Amplitude | F13: ='PLANILHA HOMOG'!Q23
C14: Valor médio apurado (R$/ha) | F14: ='PLANILHA HOMOG'!Q17 | J14: =F14*4.84
C16: VALOR DE TERRA NUA APURADO
C17: Área total do imóvel avaliando | F17: =AMOSTRAS!E13
C18: Valor do hectare (R$/ha) | F18: ='PLANILHA HOMOG'!Q17
C19: Valor total de terra nua | F19: =F17*F18
C20: Valor adotado | F20: =F19
C24: VALOR DE BENFEITORIAS - PIVÔ CENTRAL + hidraulico
C25: Custo de de Formação (novo) | F25: 2000000
C26: Depreciação: Adequada/bom | F26: 0.8
C27: Valor depreciado | F27: =F25*F26
C28: Valor adotado | F28: =F27
C31: VALOR TOTAL DE TERRA NUA + BENFEITORIAS
C32: Valor Total de Terra Nua | F32: =F20
C33: Valor do Pivô | F33: =F28
C34: Valor Total | F34: =F32+F33

Sheet LIQUIDAÇÃO
C5: ='AREA UTIL '!C4:J4
C6: CÁLCULO DE VALOR DE LIQUIDAÇÃO FORÇADA
C7: i - Taxa de Desconto | F7: 0.1075
C8: n - Número de meses | F8: 36
C9: Coeficiente Calculado | F9: =1/((1+F7)^(F8/12))
C10: Valor de Mercado | F10: =SANEAMENTO!F20
C11: Valor de Liquidação Forçada | F11: =F10/((1+F7)^(F8/12))
C13: CÁLCULO DE VALOR DE LIQUIDAÇÃO FORÇADA
C14: i - Taxa de Desconto | F14: 0.12768
C15: n - Número de meses | F15: 36
C16: Coeficiente Calculado | F16: =1/((1+F14)^(F15/12))
C17: Valor de Mercado | F17: =SANEAMENTO!F28
C18: Valor de Liquidação Forçada | F18: =F17/((1+F14)^(F15/12))

Sheet LAUDO DE AVALIAÇÃO
B2: LAUDO DE AVALIAÇÃO
B6: 014 - OBSERVAÇÕES DO AVALIADOR CÁLCULO DA TERRA NUA
W8: Avaliação Intervalar:
B9: Área avaliada (ha) | H9: x | I9: Valor homogeneizado / ha | W9: Estimativa de tendênia Central obtido
B10: =AMOSTRAS!E13 | H10: x | I10: =IF(B10=" ","",W11) | Q10: = | R10: =IF(B10=" ","",I10*B10) | W10: em planilha de Homogeneização.
W11: ='PLANILHA HOMOG'!Q17
O12: TOTAL | Q12: = | R12: =R10
B14: Outras áreas:
B15: Especificar Área (ha) | H15: x | I15: Valor homogeneizado / ha
H16: x | I16: =IF(B16=" ","",W11) | Q16: = | R16: =IF(B16=" ","",I16*B16)
O18: TOTAL | Q18: = | R18: =R16
B20: 015 - RESUMO DOS VALORES
B22: 15.1 - ÁREA AVALIADA................................................................................................................. | V22: R$ | W22: =R12
B23: 15.2 - OUTRAS ÁREAS - ESPECIFICAR................................................................................................................................... | V23: R$ | W23: =R16
B24: 15.3 - SUB-TOTAL (01)................................................................................................................................... | V24: R$ | W24: =SUM(W22:W23)
B25: 15.4 - QUADRO 12.1 - CULTURAS PERMANENTES......................................................................................... | V25: R$ | W25: ='LAUDO DE AVALIAÇÃO 12-12.4'!H9
B26: 15.5 - QUADRO 12.2 - CULTURAS TEMPORÁRIAS............................................................................................................................ | V26: R$ | W26: ='LAUDO DE AVALIAÇÃO 12-12.4'!H14
B27: 15.6 - QUADRO 12.3 - PASTAGENS ARTIFICIAIS.................................................................................................................................. | V27: R$ | W27: ='LAUDO DE AVALIAÇÃO 12-12.4'!H19
B28: 15.7 - QUADRO 12.4 - EXTRATIVISMO.................................................................................................................................. | V28: R$ | W28: ='LAUDO DE AVALIAÇÃO 12-12.4'!H24
B29: 15.8 - QUADRO 13 - BENFEITORIAS NÃO REPRODUTIVAS.......................................................................................................... | V29: R$ | W29: ='LAUDO DE AVALIAÇÃO 13'!G8
B30: 15.9 - SUB-TOTAL (02).................................................................................................................................. | V30: R$ | W30: =SUM(W25:Z29)
B31: 15.10 - TOTAL (1+2)................................................................................................................................................................ | V31: R$ | W31: =W30+W24
B32: 15.11 - MÊS BASE DA AVALIAÇÃO | K32: 43009
O33: Limite Inferior (estimativa -10%) | W33: Limite Superior (estimativa +10%)
Q34: =W31*0.9 | Y34: =W31*1.1

Sheet LAUDO DE AVALIAÇÃO 12-12.4
B1: LAUDO DE AVALIAÇÃO
B4: 12 - BENFEITORIAS REPRODUTIVAS
B5: 12.1 - CULTURAS PERMANENTES
B6: DISCRIMINAÇÃO (A) | C6: IDADE (B) | D6: ESTADO FITOSSANITÁRIO (C) | E6: UNIDADE (E) | F6: QUANTIDADE (D) | G6: VALORES EM REAIS
G7: UNITÁRIO | H7: TOTAL
H8: =TRUNC(F8*G8,2)
B9: TOTAL | H9: =TRUNC(SUM(H8:H8),2)
B10: 12.2 - CULTURAS TEMPORÁRIAS
B11: DISCRIMINAÇÃO (A) | C11: IDADE (B) | D11: ESTADO FITOSSANITÁRIO (C) | E11: UNIDADE © | F11: QUANTIDADE (D) | G11: VALORES EM REAIS
G12: UNITÁRIO | H12: TOTAL
H13: =TRUNC(F13*G13,2)
B14: TOTAL | H14: =TRUNC(SUM(H13:H13),2)
B15: 12.3 - PASTAGENS
B16: DISCRIMINAÇÃO (A) | C16: DEPRECIAÇÃO | D16: ESTADO FITOSSANITÁRIO (C) | E16: UNIDADE © | F16: QUANTIDADE (D) | G16: VALORES EM REAIS
G17: UNITÁRIO | H17: TOTAL
B18: area de pastagem andropólgon | H18: =TRUNC(F18*G18,2)
B19: TOTAL | H19: =TRUNC(SUM(H18:H18),2)
B20: 12.4 - EXTRATIVISMO
B21: DISCRIMINAÇÃO (A) | C21: IDADE (B) | D21: ESTADO FITOSSANITÁRIO (C) | E21: UNIDADE © | F21: QUANTIDADE (D) | G21: VALORES EM REAIS
G22: UNITÁRIO | H22: TOTAL
H23: =TRUNC(F23*G23,2)
B24: TOTAL

Sheet LAUDO DE AVALIAÇÃO 13
B1: LAUDO DE AVALIAÇÃO
B4: 13 - BENFEITORIAS NÃO REPRODUTIVAS
B5: DISCRIMINAÇÃO | C5: UNID. | D5: DEPREC. | E5: QUANT. | F5: VALOR EM R$ REAIS
F6: UNITÁRIO | G6: TOTAL
B8: TOTAL

Sheet quadro_resumo
A1: QUADRO RESUMO DA AVALIAÇÃO
A2: Proponente: | C2: marco antonio feitosa | J2: CPF: 713.254.791-79
A3: Proprietário: | C3: miguel phelipe feitosa | J3: CPF:713.254.791-79
A4: Proprietário: | C4: miguel phelipe feitosa gomes | J4: CNPJ:32.251.489/5614-55
A5: Agencia: | C5: ua porto nacional (14)
A6: Identificação: | C6: fazenda rancho diamante
A7: Município: | C7: palmas | J7: UF: TO
A8: MAPA DA ÁREA
A32: IMOVEL
A33: Nº Matrícula | D33: Identificação | G33: Área há | J33: Área Construída m²
A34: 1456.6547 | D34: fazenda | G34: 1234.5123 | J34: 156.65
A35: 184.096 | D35: fazenda | G35: 123.0921 | J35: 15.65
A36: VALORES
A37: Nº Matrícula | F37: Valor de mercado | K37: Liquidação forçada
A38: 1456.6547 | F38: R$ 25.000.000,00 | K38: R$ 65.000.000,00
A39: 184.096 | F39: R$ 100.000,00 | K39: R$ 1.000,00
